{"uuid": "74359f73-041e-49a2-ae21-9beebae23122", "children": ["2148e717-904c-4dfc-ac10-feb338140c2b", "65a1a1b0-ebda-4150-81e8-667d1402c0ea", "11298e96-26a0-491c-b98e-e13df23b27cd", "71d0b157-52a0-4945-bd60-65eb9c78f2a7", "a622e0fa-025c-485a-bada-032bd48a74e1", "c9c3d18f-0746-4a48-ae90-7781ee1aeb6c", "ce53e7a2-7e85-4abb-9839-9bb803f7065f", "8b740aa6-597d-4f9b-b4e7-b3742565810f", "31835844-46ec-42f4-b7a6-afbf99f8267e", "3bbc52e4-fb27-4aab-981a-636dbfd5d96c", "7d6f7fb9-88f7-46f3-a898-b6483787caf6", "fe6794c2-5a6f-493d-9370-3d81a6ba0a0c", "24feb3e7-c971-4a1b-b7ea-bf0788507b0d", "e3be2462-164a-4f44-85f3-7995053eb6cc", "c491bb22-7d26-4e54-937e-0877ae197a20", "5297bfaf-0d5e-4060-ae31-c59bcc79e344", "7e96a114-3d1e-45b2-84bd-e306e55eea3d", "6f15381f-c954-41c7-9d5b-374999dadb97", "954e0615-bbb7-42ab-bb52-b03b7faaca90", "277105e4-eade-439f-9349-9e28a0f7acc7", "db4fe1e7-0e06-42f8-858c-95b582e70fb1", "2459e9d4-1a43-4327-b4b2-2964bf9cc6db", "4b7aea66-d407-4b0f-ba1d-06162b033303", "a8625504-77e8-4f5f-802b-e42dbb118b87", "dbd3a049-23ce-4a90-86c6-bf5dc1aa7e9a", "4055405e-0272-4dad-bc1b-dc62a2ba35d3", "9fbc8830-bbef-4f63-8da5-73aa7c60cfef", "55342a8b-7853-44f7-b5c7-334aab1b5a44", "53dc2f80-c146-459c-857b-558f69ec8852", "6b00bd71-6cc6-488b-85c6-c2c75a7a6c64", "a3f4326c-2b5e-4da8-adca-6825084b7d8b", "c5d6f026-8e50-4507-a30d-301394f93af3", "7739bd5f-d040-41f8-9456-b908904af469"], "befores": [{"name": "client", "status": "broken", "statusDetails": {"message": "sqlalchemy.exc.OperationalError: (psycopg2.OperationalError) could not translate host name \"postgres\" to address: Name or service not known\n\n(Background on this error at: https://sqlalche.me/e/20/e3q8)\n", "trace": "  File \"C:\\Users\\User\\secure-auth-api\\venv\\Lib\\site-packages\\pluggy\\_callers.py\", line 38, in run_old_style_hookwrapper\n    res = yield\n          ^^^^^\n  File \"C:\\Users\\User\\secure-auth-api\\venv\\Lib\\site-packages\\pluggy\\_callers.py\", line 139, in _multicall\n    teardown.throw(exception)\n    ~~~~~~~~~~~~~~^^^^^^^^^^^\n  File \"C:\\Users\\User\\secure-auth-api\\venv\\Lib\\site-packages\\pytest_asyncio\\plugin.py\", line 681, in pytest_fixture_setup\n    return (yield)\n            ^^^^^\n  File \"C:\\Users\\User\\secure-auth-api\\venv\\Lib\\site-packages\\pluggy\\_callers.py\", line 139, in _multicall\n    teardown.throw(exception)\n    ~~~~~~~~~~~~~~^^^^^^^^^^^\n  File \"C:\\Users\\User\\secure-auth-api\\venv\\Lib\\site-packages\\pluggy\\_callers.py\", line 53, in run_old_style_hookwrapper\n    return result.get_result()\n           ~~~~~~~~~~~~~~~~~^^\n  File \"C:\\Users\\User\\secure-auth-api\\venv\\Lib\\site-packages\\pluggy\\_result.py\", line 103, in get_result\n    raise exc.with_traceback(tb)\n  File \"C:\\Users\\User\\secure-auth-api\\venv\\Lib\\site-packages\\pluggy\\_callers.py\", line 38, in run_old_style_hookwrapper\n    res = yield\n          ^^^^^\n  File \"C:\\Users\\User\\secure-auth-api\\venv\\Lib\\site-packages\\pluggy\\_callers.py\", line 139, in _multicall\n    teardown.throw(exception)\n    ~~~~~~~~~~~~~~^^^^^^^^^^^\n  File \"C:\\Users\\User\\secure-auth-api\\venv\\Lib\\site-packages\\_pytest\\setuponly.py\", line 36, in pytest_fixture_setup\n    return (yield)\n            ^^^^^\n  File \"C:\\Users\\User\\secure-auth-api\\venv\\Lib\\site-packages\\pluggy\\_callers.py\", line 121, in _multicall\n    res = hook_impl.function(*args)\n  File \"C:\\Users\\User\\secure-auth-api\\venv\\Lib\\site-packages\\_pytest\\fixtures.py\", line 1195, in pytest_fixture_setup\n    result = call_fixture_func(fixturefunc, request, kwargs)\n  File \"C:\\Users\\User\\secure-auth-api\\venv\\Lib\\site-packages\\_pytest\\fixtures.py\", line 922, in call_fixture_func\n    fixture_result = next(generator)\n  File \"C:\\Users\\User\\secure-auth-api\\tests\\conftest.py\", line 27, in client\n    Base.metadata.drop_all(bind=engine)\n    ~~~~~~~~~~~~~~~~~~~~~~^^^^^^^^^^^^^\n  File \"C:\\Users\\User\\secure-auth-api\\venv\\Lib\\site-packages\\sqlalchemy\\sql\\schema.py\", line 5952, in drop_all\n    bind._run_ddl_visitor(\n    ~~~~~~~~~~~~~~~~~~~~~^\n        ddl.SchemaDropper, self, checkfirst=checkfirst, tables=tables\n        ^^^^^^^^^^^^^^^^^^^^^^^^^^^^^^^^^^^^^^^^^^^^^^^^^^^^^^^^^^^^^\n    )\n    ^\n  File \"C:\\Users\\User\\secure-auth-api\\venv\\Lib\\site-packages\\sqlalchemy\\engine\\base.py\", line 3245, in _run_ddl_visitor\n    with self.begin() as conn:\n         ~~~~~~~~~~^^\n  File \"C:\\Python313\\Lib\\contextlib.py\", line 141, in __enter__\n    return next(self.gen)\n  File \"C:\\Users\\User\\secure-auth-api\\venv\\Lib\\site-packages\\sqlalchemy\\engine\\base.py\", line 3235, in begin\n    with self.connect() as conn:\n         ~~~~~~~~~~~~^^\n  File \"C:\\Users\\User\\secure-auth-api\\venv\\Lib\\site-packages\\sqlalchemy\\engine\\base.py\", line 3271, in connect\n    return self._connection_cls(self)\n           ~~~~~~~~~~~~~~~~~~~~^^^^^^\n  File \"C:\\Users\\User\\secure-auth-api\\venv\\Lib\\site-packages\\sqlalchemy\\engine\\base.py\", line 145, in __init__\n    Connection._handle_dbapi_exception_noconnection(\n    ~~~~~~~~~~~~~~~~~~~~~~~~~~~~~~~~~~~~~~~~~~~~~~~^\n        err, dialect, engine\n        ^^^^^^^^^^^^^^^^^^^^\n    )\n    ^\n  File \"C:\\Users\\User\\secure-auth-api\\venv\\Lib\\site-packages\\sqlalchemy\\engine\\base.py\", line 2434, in _handle_dbapi_exception_noconnection\n    raise sqlalchemy_exception.with_traceback(exc_info[2]) from e\n  File \"C:\\Users\\User\\secure-auth-api\\venv\\Lib\\site-packages\\sqlalchemy\\engine\\base.py\", line 143, in __init__\n    self._dbapi_connection = engine.raw_connection()\n                             ~~~~~~~~~~~~~~~~~~~~~^^\n  File \"C:\\Users\\User\\secure-auth-api\\venv\\Lib\\site-packages\\sqlalchemy\\engine\\base.py\", line 3295, in raw_connection\n    return self.pool.connect()\n           ~~~~~~~~~~~~~~~~~^^\n  File \"C:\\Users\\User\\secure-auth-api\\venv\\Lib\\site-packages\\sqlalchemy\\pool\\base.py\", line 447, in connect\n    return _ConnectionFairy._checkout(self)\n           ~~~~~~~~~~~~~~~~~~~~~~~~~~^^^^^^\n  File \"C:\\Users\\User\\secure-auth-api\\venv\\Lib\\site-packages\\sqlalchemy\\pool\\base.py\", line 1264, in _checkout\n    fairy = _ConnectionRecord.checkout(pool)\n  File \"C:\\Users\\User\\secure-auth-api\\venv\\Lib\\site-packages\\sqlalchemy\\pool\\base.py\", line 711, in checkout\n    rec = pool._do_get()\n  File \"C:\\Users\\User\\secure-auth-api\\venv\\Lib\\site-packages\\sqlalchemy\\pool\\impl.py\", line 177, in _do_get\n    with util.safe_reraise():\n         ~~~~~~~~~~~~~~~~~^^\n  File \"C:\\Users\\User\\secure-auth-api\\venv\\Lib\\site-packages\\sqlalchemy\\util\\langhelpers.py\", line 224, in __exit__\n    raise exc_value.with_traceback(exc_tb)\n  File \"C:\\Users\\User\\secure-auth-api\\venv\\Lib\\site-packages\\sqlalchemy\\pool\\impl.py\", line 175, in _do_get\n    return self._create_connection()\n           ~~~~~~~~~~~~~~~~~~~~~~~^^\n  File \"C:\\Users\\User\\secure-auth-api\\venv\\Lib\\site-packages\\sqlalchemy\\pool\\base.py\", line 388, in _create_connection\n    return _ConnectionRecord(self)\n  File \"C:\\Users\\User\\secure-auth-api\\venv\\Lib\\site-packages\\sqlalchemy\\pool\\base.py\", line 673, in __init__\n    self.__connect()\n    ~~~~~~~~~~~~~~^^\n  File \"C:\\Users\\User\\secure-auth-api\\venv\\Lib\\site-packages\\sqlalchemy\\pool\\base.py\", line 899, in __connect\n    with util.safe_reraise():\n         ~~~~~~~~~~~~~~~~~^^\n  File \"C:\\Users\\User\\secure-auth-api\\venv\\Lib\\site-packages\\sqlalchemy\\util\\langhelpers.py\", line 224, in __exit__\n    raise exc_value.with_traceback(exc_tb)\n  File \"C:\\Users\\User\\secure-auth-api\\venv\\Lib\\site-packages\\sqlalchemy\\pool\\base.py\", line 895, in __connect\n    self.dbapi_connection = connection = pool._invoke_creator(self)\n                                         ~~~~~~~~~~~~~~~~~~~~^^^^^^\n  File \"C:\\Users\\User\\secure-auth-api\\venv\\Lib\\site-packages\\sqlalchemy\\engine\\create.py\", line 646, in connect\n    return dialect.connect(*cargs, **cparams)\n           ~~~~~~~~~~~~~~~^^^^^^^^^^^^^^^^^^^\n  File \"C:\\Users\\User\\secure-auth-api\\venv\\Lib\\site-packages\\sqlalchemy\\engine\\default.py\", line 626, in connect\n    return self.loaded_dbapi.connect(*cargs, **cparams)  # type: ignore[no-any-return]  # NOQA: E501\n           ~~~~~~~~~~~~~~~~~~~~~~~~~^^^^^^^^^^^^^^^^^^^\n  File \"C:\\Users\\User\\secure-auth-api\\venv\\Lib\\site-packages\\psycopg2\\__init__.py\", line 135, in connect\n    conn = _connect(dsn, connection_factory=connection_factory, **kwasync)\n"}, "start": 1754498467831, "stop": 1754498470644}], "start": 1754498467831, "stop": 1754498492183}