{"uuid": "ca63e7b1-808e-4346-a112-3573f35b6430", "children": ["43c0d902-e17c-4fe2-b1b5-73c88c5fb22a", "70e31610-a598-4eff-87c5-9ea55593fa5a", "fa45faa8-e3e5-4819-8f8a-c53bc004a762", "9495e8d5-0a36-4e6d-95f2-e0d0d0c38c27", "b839d5f3-4f59-464a-8862-8cc1cb0f49a3", "97274c23-5288-417f-af69-04aa29472482", "fa110c09-a43e-48b6-8d1c-0535cc275c5e", "5e9e2425-cc72-4321-b503-99f7f47b44fa", "28776795-efbd-4a95-9d48-f5d5c101c64d", "a04862a2-c752-4967-8f14-fe1278eddc1a", "0b3c3043-07f2-48ae-af44-452edd8698fb", "59846d9a-43e4-4d37-9bc5-5c8729b3dffc", "1d775e06-5428-44c7-8209-d8a6d779129d", "5ef2619f-e654-48c9-89b6-27ea4d5f8792", "3723a630-820d-4fe0-b295-a5badad3f556", "b2305974-09c5-4803-89a4-a70b330e0b82", "79924f6c-c2f3-4d61-9e8b-cd60452307d9", "f60fca6d-2503-48b1-9e40-48116bf30c28", "8cc95278-4355-4523-ab19-872e4f030810", "19d8d0b7-9ee3-44ef-b957-9876689d46bc", "e900a363-e36d-47c1-a727-33bc410ec1ea", "3151611a-b0fb-4f89-a00b-ca12ad171e15", "78df86ec-1175-4a72-8d36-0ceb6cbfe14e", "b4ce10d5-8fc2-42f1-a556-cc8eb6348e31", "dada80da-2049-492c-ad56-61859596f444", "5fae6817-3a99-4397-89b8-805293c84051", "836145f5-7ca9-4ad3-a4af-e6ff7274c0e3", "fa6c5d84-0805-42cc-aebf-d5aae6421aed", "5d9d12dd-b811-4a49-9a56-e9d9a32e0023", "c892c440-7ee4-44d6-a9e8-3f94e115db7b", "4ac10927-0d47-4923-9994-56982d3033e4", "d85bb2ba-7fe1-4d6c-899f-1c8e2e86e74f", "d87a7765-f3a6-479a-870d-10e4fbadbbf6"], "befores": [{"name": "client", "status": "broken", "statusDetails": {"message": "sqlalchemy.exc.OperationalError: (psycopg2.OperationalError) could not translate host name \"postgres\" to address: Name or service not known\n\n(Background on this error at: https://sqlalche.me/e/20/e3q8)\n", "trace": "  File \"C:\\Users\\User\\secure-auth-api\\venv\\Lib\\site-packages\\pluggy\\_callers.py\", line 38, in run_old_style_hookwrapper\n    res = yield\n          ^^^^^\n  File \"C:\\Users\\User\\secure-auth-api\\venv\\Lib\\site-packages\\pluggy\\_callers.py\", line 139, in _multicall\n    teardown.throw(exception)\n    ~~~~~~~~~~~~~~^^^^^^^^^^^\n  File \"C:\\Users\\User\\secure-auth-api\\venv\\Lib\\site-packages\\pytest_asyncio\\plugin.py\", line 681, in pytest_fixture_setup\n    return (yield)\n            ^^^^^\n  File \"C:\\Users\\User\\secure-auth-api\\venv\\Lib\\site-packages\\pluggy\\_callers.py\", line 139, in _multicall\n    teardown.throw(exception)\n    ~~~~~~~~~~~~~~^^^^^^^^^^^\n  File \"C:\\Users\\User\\secure-auth-api\\venv\\Lib\\site-packages\\pluggy\\_callers.py\", line 53, in run_old_style_hookwrapper\n    return result.get_result()\n           ~~~~~~~~~~~~~~~~~^^\n  File \"C:\\Users\\User\\secure-auth-api\\venv\\Lib\\site-packages\\pluggy\\_result.py\", line 103, in get_result\n    raise exc.with_traceback(tb)\n  File \"C:\\Users\\User\\secure-auth-api\\venv\\Lib\\site-packages\\pluggy\\_callers.py\", line 38, in run_old_style_hookwrapper\n    res = yield\n          ^^^^^\n  File \"C:\\Users\\User\\secure-auth-api\\venv\\Lib\\site-packages\\pluggy\\_callers.py\", line 139, in _multicall\n    teardown.throw(exception)\n    ~~~~~~~~~~~~~~^^^^^^^^^^^\n  File \"C:\\Users\\User\\secure-auth-api\\venv\\Lib\\site-packages\\_pytest\\setuponly.py\", line 36, in pytest_fixture_setup\n    return (yield)\n            ^^^^^\n  File \"C:\\Users\\User\\secure-auth-api\\venv\\Lib\\site-packages\\pluggy\\_callers.py\", line 121, in _multicall\n    res = hook_impl.function(*args)\n  File \"C:\\Users\\User\\secure-auth-api\\venv\\Lib\\site-packages\\_pytest\\fixtures.py\", line 1195, in pytest_fixture_setup\n    result = call_fixture_func(fixturefunc, request, kwargs)\n  File \"C:\\Users\\User\\secure-auth-api\\venv\\Lib\\site-packages\\_pytest\\fixtures.py\", line 922, in call_fixture_func\n    fixture_result = next(generator)\n  File \"C:\\Users\\User\\secure-auth-api\\tests\\conftest.py\", line 27, in client\n    Base.metadata.drop_all(bind=engine)\n    ~~~~~~~~~~~~~~~~~~~~~~^^^^^^^^^^^^^\n  File \"C:\\Users\\User\\secure-auth-api\\venv\\Lib\\site-packages\\sqlalchemy\\sql\\schema.py\", line 5952, in drop_all\n    bind._run_ddl_visitor(\n    ~~~~~~~~~~~~~~~~~~~~~^\n        ddl.SchemaDropper, self, checkfirst=checkfirst, tables=tables\n        ^^^^^^^^^^^^^^^^^^^^^^^^^^^^^^^^^^^^^^^^^^^^^^^^^^^^^^^^^^^^^\n    )\n    ^\n  File \"C:\\Users\\User\\secure-auth-api\\venv\\Lib\\site-packages\\sqlalchemy\\engine\\base.py\", line 3245, in _run_ddl_visitor\n    with self.begin() as conn:\n         ~~~~~~~~~~^^\n  File \"C:\\Python313\\Lib\\contextlib.py\", line 141, in __enter__\n    return next(self.gen)\n  File \"C:\\Users\\User\\secure-auth-api\\venv\\Lib\\site-packages\\sqlalchemy\\engine\\base.py\", line 3235, in begin\n    with self.connect() as conn:\n         ~~~~~~~~~~~~^^\n  File \"C:\\Users\\User\\secure-auth-api\\venv\\Lib\\site-packages\\sqlalchemy\\engine\\base.py\", line 3271, in connect\n    return self._connection_cls(self)\n           ~~~~~~~~~~~~~~~~~~~~^^^^^^\n  File \"C:\\Users\\User\\secure-auth-api\\venv\\Lib\\site-packages\\sqlalchemy\\engine\\base.py\", line 145, in __init__\n    Connection._handle_dbapi_exception_noconnection(\n    ~~~~~~~~~~~~~~~~~~~~~~~~~~~~~~~~~~~~~~~~~~~~~~~^\n        err, dialect, engine\n        ^^^^^^^^^^^^^^^^^^^^\n    )\n    ^\n  File \"C:\\Users\\User\\secure-auth-api\\venv\\Lib\\site-packages\\sqlalchemy\\engine\\base.py\", line 2434, in _handle_dbapi_exception_noconnection\n    raise sqlalchemy_exception.with_traceback(exc_info[2]) from e\n  File \"C:\\Users\\User\\secure-auth-api\\venv\\Lib\\site-packages\\sqlalchemy\\engine\\base.py\", line 143, in __init__\n    self._dbapi_connection = engine.raw_connection()\n                             ~~~~~~~~~~~~~~~~~~~~~^^\n  File \"C:\\Users\\User\\secure-auth-api\\venv\\Lib\\site-packages\\sqlalchemy\\engine\\base.py\", line 3295, in raw_connection\n    return self.pool.connect()\n           ~~~~~~~~~~~~~~~~~^^\n  File \"C:\\Users\\User\\secure-auth-api\\venv\\Lib\\site-packages\\sqlalchemy\\pool\\base.py\", line 447, in connect\n    return _ConnectionFairy._checkout(self)\n           ~~~~~~~~~~~~~~~~~~~~~~~~~~^^^^^^\n  File \"C:\\Users\\User\\secure-auth-api\\venv\\Lib\\site-packages\\sqlalchemy\\pool\\base.py\", line 1264, in _checkout\n    fairy = _ConnectionRecord.checkout(pool)\n  File \"C:\\Users\\User\\secure-auth-api\\venv\\Lib\\site-packages\\sqlalchemy\\pool\\base.py\", line 711, in checkout\n    rec = pool._do_get()\n  File \"C:\\Users\\User\\secure-auth-api\\venv\\Lib\\site-packages\\sqlalchemy\\pool\\impl.py\", line 177, in _do_get\n    with util.safe_reraise():\n         ~~~~~~~~~~~~~~~~~^^\n  File \"C:\\Users\\User\\secure-auth-api\\venv\\Lib\\site-packages\\sqlalchemy\\util\\langhelpers.py\", line 224, in __exit__\n    raise exc_value.with_traceback(exc_tb)\n  File \"C:\\Users\\User\\secure-auth-api\\venv\\Lib\\site-packages\\sqlalchemy\\pool\\impl.py\", line 175, in _do_get\n    return self._create_connection()\n           ~~~~~~~~~~~~~~~~~~~~~~~^^\n  File \"C:\\Users\\User\\secure-auth-api\\venv\\Lib\\site-packages\\sqlalchemy\\pool\\base.py\", line 388, in _create_connection\n    return _ConnectionRecord(self)\n  File \"C:\\Users\\User\\secure-auth-api\\venv\\Lib\\site-packages\\sqlalchemy\\pool\\base.py\", line 673, in __init__\n    self.__connect()\n    ~~~~~~~~~~~~~~^^\n  File \"C:\\Users\\User\\secure-auth-api\\venv\\Lib\\site-packages\\sqlalchemy\\pool\\base.py\", line 899, in __connect\n    with util.safe_reraise():\n         ~~~~~~~~~~~~~~~~~^^\n  File \"C:\\Users\\User\\secure-auth-api\\venv\\Lib\\site-packages\\sqlalchemy\\util\\langhelpers.py\", line 224, in __exit__\n    raise exc_value.with_traceback(exc_tb)\n  File \"C:\\Users\\User\\secure-auth-api\\venv\\Lib\\site-packages\\sqlalchemy\\pool\\base.py\", line 895, in __connect\n    self.dbapi_connection = connection = pool._invoke_creator(self)\n                                         ~~~~~~~~~~~~~~~~~~~~^^^^^^\n  File \"C:\\Users\\User\\secure-auth-api\\venv\\Lib\\site-packages\\sqlalchemy\\engine\\create.py\", line 646, in connect\n    return dialect.connect(*cargs, **cparams)\n           ~~~~~~~~~~~~~~~^^^^^^^^^^^^^^^^^^^\n  File \"C:\\Users\\User\\secure-auth-api\\venv\\Lib\\site-packages\\sqlalchemy\\engine\\default.py\", line 626, in connect\n    return self.loaded_dbapi.connect(*cargs, **cparams)  # type: ignore[no-any-return]  # NOQA: E501\n           ~~~~~~~~~~~~~~~~~~~~~~~~~^^^^^^^^^^^^^^^^^^^\n  File \"C:\\Users\\User\\secure-auth-api\\venv\\Lib\\site-packages\\psycopg2\\__init__.py\", line 135, in connect\n    conn = _connect(dsn, connection_factory=connection_factory, **kwasync)\n"}, "start": 1754498397000, "stop": 1754498399833}], "start": 1754498397000, "stop": 1754498425060}