{"uuid": "94376f29-1377-4858-91a5-5be5679ec2a9", "befores": [{"name": "client", "status": "broken", "statusDetails": {"message": "sqlalchemy.exc.OperationalError: (psycopg2.OperationalError) could not translate host name \"postgres\" to address: Name or service not known\n\n(Background on this error at: https://sqlalche.me/e/20/e3q8)\n", "trace": "  File \"C:\\Users\\User\\AppData\\Roaming\\Python\\Python313\\site-packages\\pluggy\\_callers.py\", line 38, in run_old_style_hookwrapper\n    res = yield\n          ^^^^^\n  File \"C:\\Users\\User\\AppData\\Roaming\\Python\\Python313\\site-packages\\pluggy\\_callers.py\", line 139, in _multicall\n    teardown.throw(exception)\n    ~~~~~~~~~~~~~~^^^^^^^^^^^\n  File \"C:\\Users\\User\\AppData\\Roaming\\Python\\Python313\\site-packages\\pytest_asyncio\\plugin.py\", line 681, in pytest_fixture_setup\n    return (yield)\n            ^^^^^\n  File \"C:\\Users\\User\\AppData\\Roaming\\Python\\Python313\\site-packages\\pluggy\\_callers.py\", line 139, in _multicall\n    teardown.throw(exception)\n    ~~~~~~~~~~~~~~^^^^^^^^^^^\n  File \"C:\\Users\\User\\AppData\\Roaming\\Python\\Python313\\site-packages\\pluggy\\_callers.py\", line 53, in run_old_style_hookwrapper\n    return result.get_result()\n           ~~~~~~~~~~~~~~~~~^^\n  File \"C:\\Users\\User\\AppData\\Roaming\\Python\\Python313\\site-packages\\pluggy\\_result.py\", line 103, in get_result\n    raise exc.with_traceback(tb)\n  File \"C:\\Users\\User\\AppData\\Roaming\\Python\\Python313\\site-packages\\pluggy\\_callers.py\", line 38, in run_old_style_hookwrapper\n    res = yield\n          ^^^^^\n  File \"C:\\Users\\User\\AppData\\Roaming\\Python\\Python313\\site-packages\\pluggy\\_callers.py\", line 139, in _multicall\n    teardown.throw(exception)\n    ~~~~~~~~~~~~~~^^^^^^^^^^^\n  File \"C:\\Users\\User\\AppData\\Roaming\\Python\\Python313\\site-packages\\_pytest\\setuponly.py\", line 36, in pytest_fixture_setup\n    return (yield)\n            ^^^^^\n  File \"C:\\Users\\User\\AppData\\Roaming\\Python\\Python313\\site-packages\\pluggy\\_callers.py\", line 121, in _multicall\n    res = hook_impl.function(*args)\n  File \"C:\\Users\\User\\AppData\\Roaming\\Python\\Python313\\site-packages\\_pytest\\fixtures.py\", line 1195, in pytest_fixture_setup\n    result = call_fixture_func(fixturefunc, request, kwargs)\n  File \"C:\\Users\\User\\AppData\\Roaming\\Python\\Python313\\site-packages\\_pytest\\fixtures.py\", line 922, in call_fixture_func\n    fixture_result = next(generator)\n  File \"C:\\Users\\User\\secure-auth-api\\tests\\conftest.py\", line 27, in client\n    Base.metadata.drop_all(bind=engine)\n    ~~~~~~~~~~~~~~~~~~~~~~^^^^^^^^^^^^^\n  File \"C:\\Users\\User\\AppData\\Roaming\\Python\\Python313\\site-packages\\sqlalchemy\\sql\\schema.py\", line 5952, in drop_all\n    bind._run_ddl_visitor(\n    ~~~~~~~~~~~~~~~~~~~~~^\n        ddl.SchemaDropper, self, checkfirst=checkfirst, tables=tables\n        ^^^^^^^^^^^^^^^^^^^^^^^^^^^^^^^^^^^^^^^^^^^^^^^^^^^^^^^^^^^^^\n    )\n    ^\n  File \"C:\\Users\\User\\AppData\\Roaming\\Python\\Python313\\site-packages\\sqlalchemy\\engine\\base.py\", line 3245, in _run_ddl_visitor\n    with self.begin() as conn:\n         ~~~~~~~~~~^^\n  File \"C:\\Python313\\Lib\\contextlib.py\", line 141, in __enter__\n    return next(self.gen)\n  File \"C:\\Users\\User\\AppData\\Roaming\\Python\\Python313\\site-packages\\sqlalchemy\\engine\\base.py\", line 3235, in begin\n    with self.connect() as conn:\n         ~~~~~~~~~~~~^^\n  File \"C:\\Users\\User\\AppData\\Roaming\\Python\\Python313\\site-packages\\sqlalchemy\\engine\\base.py\", line 3271, in connect\n    return self._connection_cls(self)\n           ~~~~~~~~~~~~~~~~~~~~^^^^^^\n  File \"C:\\Users\\User\\AppData\\Roaming\\Python\\Python313\\site-packages\\sqlalchemy\\engine\\base.py\", line 145, in __init__\n    Connection._handle_dbapi_exception_noconnection(\n    ~~~~~~~~~~~~~~~~~~~~~~~~~~~~~~~~~~~~~~~~~~~~~~~^\n        err, dialect, engine\n        ^^^^^^^^^^^^^^^^^^^^\n    )\n    ^\n  File \"C:\\Users\\User\\AppData\\Roaming\\Python\\Python313\\site-packages\\sqlalchemy\\engine\\base.py\", line 2434, in _handle_dbapi_exception_noconnection\n    raise sqlalchemy_exception.with_traceback(exc_info[2]) from e\n  File \"C:\\Users\\User\\AppData\\Roaming\\Python\\Python313\\site-packages\\sqlalchemy\\engine\\base.py\", line 143, in __init__\n    self._dbapi_connection = engine.raw_connection()\n                             ~~~~~~~~~~~~~~~~~~~~~^^\n  File \"C:\\Users\\User\\AppData\\Roaming\\Python\\Python313\\site-packages\\sqlalchemy\\engine\\base.py\", line 3295, in raw_connection\n    return self.pool.connect()\n           ~~~~~~~~~~~~~~~~~^^\n  File \"C:\\Users\\User\\AppData\\Roaming\\Python\\Python313\\site-packages\\sqlalchemy\\pool\\base.py\", line 447, in connect\n    return _ConnectionFairy._checkout(self)\n           ~~~~~~~~~~~~~~~~~~~~~~~~~~^^^^^^\n  File \"C:\\Users\\User\\AppData\\Roaming\\Python\\Python313\\site-packages\\sqlalchemy\\pool\\base.py\", line 1264, in _checkout\n    fairy = _ConnectionRecord.checkout(pool)\n  File \"C:\\Users\\User\\AppData\\Roaming\\Python\\Python313\\site-packages\\sqlalchemy\\pool\\base.py\", line 711, in checkout\n    rec = pool._do_get()\n  File \"C:\\Users\\User\\AppData\\Roaming\\Python\\Python313\\site-packages\\sqlalchemy\\pool\\impl.py\", line 177, in _do_get\n    with util.safe_reraise():\n         ~~~~~~~~~~~~~~~~~^^\n  File \"C:\\Users\\User\\AppData\\Roaming\\Python\\Python313\\site-packages\\sqlalchemy\\util\\langhelpers.py\", line 224, in __exit__\n    raise exc_value.with_traceback(exc_tb)\n  File \"C:\\Users\\User\\AppData\\Roaming\\Python\\Python313\\site-packages\\sqlalchemy\\pool\\impl.py\", line 175, in _do_get\n    return self._create_connection()\n           ~~~~~~~~~~~~~~~~~~~~~~~^^\n  File \"C:\\Users\\User\\AppData\\Roaming\\Python\\Python313\\site-packages\\sqlalchemy\\pool\\base.py\", line 388, in _create_connection\n    return _ConnectionRecord(self)\n  File \"C:\\Users\\User\\AppData\\Roaming\\Python\\Python313\\site-packages\\sqlalchemy\\pool\\base.py\", line 673, in __init__\n    self.__connect()\n    ~~~~~~~~~~~~~~^^\n  File \"C:\\Users\\User\\AppData\\Roaming\\Python\\Python313\\site-packages\\sqlalchemy\\pool\\base.py\", line 899, in __connect\n    with util.safe_reraise():\n         ~~~~~~~~~~~~~~~~~^^\n  File \"C:\\Users\\User\\AppData\\Roaming\\Python\\Python313\\site-packages\\sqlalchemy\\util\\langhelpers.py\", line 224, in __exit__\n    raise exc_value.with_traceback(exc_tb)\n  File \"C:\\Users\\User\\AppData\\Roaming\\Python\\Python313\\site-packages\\sqlalchemy\\pool\\base.py\", line 895, in __connect\n    self.dbapi_connection = connection = pool._invoke_creator(self)\n                                         ~~~~~~~~~~~~~~~~~~~~^^^^^^\n  File \"C:\\Users\\User\\AppData\\Roaming\\Python\\Python313\\site-packages\\sqlalchemy\\engine\\create.py\", line 646, in connect\n    return dialect.connect(*cargs, **cparams)\n           ~~~~~~~~~~~~~~~^^^^^^^^^^^^^^^^^^^\n  File \"C:\\Users\\User\\AppData\\Roaming\\Python\\Python313\\site-packages\\sqlalchemy\\engine\\default.py\", line 626, in connect\n    return self.loaded_dbapi.connect(*cargs, **cparams)  # type: ignore[no-any-return]  # NOQA: E501\n           ~~~~~~~~~~~~~~~~~~~~~~~~~^^^^^^^^^^^^^^^^^^^\n  File \"C:\\Users\\User\\AppData\\Roaming\\Python\\Python313\\site-packages\\psycopg2\\__init__.py\", line 135, in connect\n    conn = _connect(dsn, connection_factory=connection_factory, **kwasync)\n"}, "start": 1754497505149, "stop": 1754497507964}], "start": 1754497505149, "stop": 1754497514364}